Traceback (most recent call last):
  File "/anaconda3/envs/myenv/lib/python3.9/site-packages/jupyter_cache/executors/utils.py", line 51, in single_nb_execution
    executenb(
  File "/anaconda3/envs/myenv/lib/python3.9/site-packages/nbclient/client.py", line 1117, in execute
    return NotebookClient(nb=nb, resources=resources, km=km, **kwargs).execute()
  File "/anaconda3/envs/myenv/lib/python3.9/site-packages/nbclient/util.py", line 78, in wrapped
    return just_run(coro(*args, **kwargs))
  File "/anaconda3/envs/myenv/lib/python3.9/site-packages/nbclient/util.py", line 57, in just_run
    return loop.run_until_complete(coro)
  File "/anaconda3/envs/myenv/lib/python3.9/asyncio/base_events.py", line 642, in run_until_complete
    return future.result()
  File "/anaconda3/envs/myenv/lib/python3.9/site-packages/nbclient/client.py", line 558, in async_execute
    await self.async_execute_cell(
  File "/anaconda3/envs/myenv/lib/python3.9/site-packages/nbclient/client.py", line 862, in async_execute_cell
    self._check_raise_for_error(cell, exec_reply)
  File "/anaconda3/envs/myenv/lib/python3.9/site-packages/nbclient/client.py", line 765, in _check_raise_for_error
    raise CellExecutionError.from_cell_and_msg(cell, exec_reply_content)
nbclient.exceptions.CellExecutionError: An error occurred while executing the following cell:
------------------
# write your code for solving probelm 2 in this cell

# You can load CIFAR-10 dataset as follows:
CIFAR10_transform = torchvision.transforms.Compose([torchvision.transforms.ToTensor()])

trainset = torchvision.datasets.CIFAR10(root='./data', train=True, download=True, transform=CIFAR10_transform)
trainloader = torch.utils.data.DataLoader(trainset, batch_size=128, shuffle=True)

testset = torchvision.datasets.CIFAR10(root='./data', train=False, download=True, transform=CIFAR10_transform)
testloader = torch.utils.data.DataLoader(testset, batch_size=1, shuffle=False)
------------------

[0;31m---------------------------------------------------------------------------[0m
[0;31mNameError[0m                                 Traceback (most recent call last)
[0;32m/var/folders/xz/fhb2zgq551315f5zf88k__ph0000gn/T/ipykernel_27357/1679944520.py[0m in [0;36m<module>[0;34m[0m
[1;32m      2[0m [0;34m[0m[0m
[1;32m      3[0m [0;31m# You can load CIFAR-10 dataset as follows:[0m[0;34m[0m[0;34m[0m[0;34m[0m[0m
[0;32m----> 4[0;31m [0mCIFAR10_transform[0m [0;34m=[0m [0mtorchvision[0m[0;34m.[0m[0mtransforms[0m[0;34m.[0m[0mCompose[0m[0;34m([0m[0;34m[[0m[0mtorchvision[0m[0;34m.[0m[0mtransforms[0m[0;34m.[0m[0mToTensor[0m[0;34m([0m[0;34m)[0m[0;34m][0m[0;34m)[0m[0;34m[0m[0;34m[0m[0m
[0m[1;32m      5[0m [0;34m[0m[0m
[1;32m      6[0m [0mtrainset[0m [0;34m=[0m [0mtorchvision[0m[0;34m.[0m[0mdatasets[0m[0;34m.[0m[0mCIFAR10[0m[0;34m([0m[0mroot[0m[0;34m=[0m[0;34m'./data'[0m[0;34m,[0m [0mtrain[0m[0;34m=[0m[0;32mTrue[0m[0;34m,[0m [0mdownload[0m[0;34m=[0m[0;32mTrue[0m[0;34m,[0m [0mtransform[0m[0;34m=[0m[0mCIFAR10_transform[0m[0;34m)[0m[0;34m[0m[0;34m[0m[0m

[0;31mNameError[0m: name 'torchvision' is not defined
NameError: name 'torchvision' is not defined

