Traceback (most recent call last):
  File "/anaconda3/envs/myenv/lib/python3.9/site-packages/jupyter_cache/executors/utils.py", line 51, in single_nb_execution
    executenb(
  File "/anaconda3/envs/myenv/lib/python3.9/site-packages/nbclient/client.py", line 1117, in execute
    return NotebookClient(nb=nb, resources=resources, km=km, **kwargs).execute()
  File "/anaconda3/envs/myenv/lib/python3.9/site-packages/nbclient/util.py", line 78, in wrapped
    return just_run(coro(*args, **kwargs))
  File "/anaconda3/envs/myenv/lib/python3.9/site-packages/nbclient/util.py", line 57, in just_run
    return loop.run_until_complete(coro)
  File "/anaconda3/envs/myenv/lib/python3.9/asyncio/base_events.py", line 642, in run_until_complete
    return future.result()
  File "/anaconda3/envs/myenv/lib/python3.9/site-packages/nbclient/client.py", line 558, in async_execute
    await self.async_execute_cell(
  File "/anaconda3/envs/myenv/lib/python3.9/site-packages/nbclient/client.py", line 862, in async_execute_cell
    self._check_raise_for_error(cell, exec_reply)
  File "/anaconda3/envs/myenv/lib/python3.9/site-packages/nbclient/client.py", line 765, in _check_raise_for_error
    raise CellExecutionError.from_cell_and_msg(cell, exec_reply_content)
nbclient.exceptions.CellExecutionError: An error occurred while executing the following cell:
------------------
 def model(100,10):
    return nn.Linear(100,10)
 
------------------

[0;36m  File [0;32m"/var/folders/xz/fhb2zgq551315f5zf88k__ph0000gn/T/ipykernel_27339/4021576493.py"[0;36m, line [0;32m1[0m
[0;31m    def model(100,10):[0m
[0m              ^[0m
[0;31mSyntaxError[0m[0;31m:[0m invalid syntax

SyntaxError: invalid syntax (4021576493.py, line 1)

